#### 注意事项：
- 异常分为3种：
    1. Error(应用外异常，比如硬件原因)
    2. RuntimeException及其子类(应用内异常，比如NullPointerException，通常是程序bug导致)
    3. CheckedException(其他异常，可在编译时发现)
- 对于任何可能抛出CheckedException的代码，必须被二者之一包围，否则无法通过编译：
    - try..catch语句块
    - 一个加上throws..的方法
- RuntimeException可以通过try..catch捕获，防止应用异常退出
- 在jdk1.7及以后，可以把多个相同的catch处理块合并在一起，例如：

        catch (IOException|SQLException ex) {
            logger.log(ex);
            throw ex;
        }
        
    不同的异常类型之间加分隔符"|"。注意这样加分隔符写的话，ex隐含了final修饰符，即不能给ex另外赋值
- 在虚拟机未关闭或线程未被打断的情况下，必定会执行finally块，无论try块跟catch块发生了什么，
    包括发生错误、正常执行、try或catch块出现return语句。
- 如果try块或catch块和finally块同时有return语句，函数返回结果以finally的为准，  
    但是try或catch里return后面的表达式还会计算，而且在finally执行前计算
- try{}块紧随其后的必须是catch块或finally块，可以只有finally块而没有catch块
- try{}块里面遇到错误，try{}里面接下去的语句肯定不会执行
- 对于Checked Exception，有try必须要有catch或throws，不能只是try..finally就结束
- 如果try块和finally块同时都抛出异常(没有catch块)，则try块抛出的会被隐藏，以finally块的为准
- 可以采用try(AutoCloseable定义语句){...}，即try..with语句，后面可以没有catch或finally，
    可以用来省略finally里的关闭资源方法，如果有catch或finally块，则这些块在资源关闭后执行
- Unchecked Exception可以既不catch，也不在方法声明后面throws
- Checked Exception可以一直抛出到main方法外面，此时会触发printStackTrace
- 未捕获的异常会在第一行开头写"Exception in thread main"，其他与已捕获的异常相同